<robot name = "robot">
    <link name="Link1">
        <inertial>
            <origin xyz="0 0 0.19007251402970268" rpy="0 0 0"/>
            <mass value="1" />
            <inertia ixx="100" ixy="0" ixz="0" iyy="100" iyz="0" izz="100" />
        </inertial>
        <visual>
            <origin xyz="0 0 0.19007251402970268" rpy="0 0 0"/>
            <geometry>
                <box size="0.221409318973732 0.03321225170151271 0.38014502805940537" />
            </geometry>
            <material name="Cyan">
                <color rgba="0 1.0 1.0 1.0"/>
            </material>
        </visual>
        <collision>
            <origin xyz="0 0 0.19007251402970268" rpy="0 0 0"/>
            <geometry>
                <box size="0.221409318973732 0.03321225170151271 0.38014502805940537" />
            </geometry>
        </collision>
    </link>
    <joint name="Link1_Link2" type="revolute">
       <parent link="Link1"/>
       <child  link="Link2"/>
       <origin rpy="0 0 0" xyz="0.110704659486866 0 0.38014502805940537" />
       <axis xyz="0 1 0"/>
       <limit effort="0.0" lower="-3.14159" upper="3.14159" velocity="0.0"/>
    </joint>
    <link name="Link2">
        <inertial>
            <origin xyz="0.1633572181040469 0 0.2138246956530414" rpy="0 0 0"/>
            <mass value="1" />
            <inertia ixx="100" ixy="0" ixz="0" iyy="100" iyz="0" izz="100" />
        </inertial>
        <visual>
            <origin xyz="0.1633572181040469 0 0.2138246956530414" rpy="0 0 0"/>
            <geometry>
                <box size="0.3267144362080938 0.0725489880034792 0.4276493913060828" />
            </geometry>
            <material name="Cyan">
                <color rgba="0 1.0 1.0 1.0"/>
            </material>
        </visual>
        <collision>
            <origin xyz="0.1633572181040469 0 0.2138246956530414" rpy="0 0 0"/>
            <geometry>
                <box size="0.3267144362080938 0.0725489880034792 0.4276493913060828" />
            </geometry>
        </collision>
    </link>
</robot>